<?xml version="1.0"?>

<robot xmlns:xacro="http://ros.org/wiki/xacro">

    <!-- Configure ZENMUSE Gimbal -->
    <xacro:macro
      name="gimbal_laser"
      params="namespace
              parent_link
              pose_topic
              visualize
              *origin">
    <xacro:gimbal_plugin_macro
      namespace="${namespace}"
      parent_link="${parent_link}"
      pose_topic="${pose_topic}"
      visualize="${visualize}"
      mass="0.00001"
      x_rotation_range="1000"
      y_rotation_range="1000"
      z_rotation_range="1000"
      time_constant="0.00001">
      <inertia ixx="0.00001" ixy="0.0" ixz="0.0" iyy="0.00001" iyz="0.0" izz="0.00001" />
      <xacro:insert_block name="origin" />
    </xacro:gimbal_plugin_macro>
  </xacro:macro>

    <!-- Macro to add a Gimbal -->
  <xacro:macro
    name="gimbal_plugin_macro"
    params="namespace parent_link pose_topic visualize mass x_rotation_range 
            y_rotation_range z_rotation_range time_constant *inertia *origin">


    <link name="${namespace}/gimbal/base_link">
      <inertial>
        <inertia ixx="0.00001" ixy="0.0" ixz="0.0" iyy="0.00001" iyz="0.0" izz="0.00001" />
        <mass value="${mass}" />
        <xacro:insert_block name="origin" />
      </inertial>
    </link>


    <joint name="${namespace}/gimbal_base_joint" type="revolute">
      <xacro:insert_block name="origin" />
      <parent link="${parent_link}" />
      <child link="${namespace}/gimbal/base_link" />
      <limit upper="0" lower="0" effort="0" velocity="0"/>
    </joint>

    <link name="${namespace}/gimbal/yaw_link">
      <inertial>
        <inertia ixx="0.00001" ixy="0.0" ixz="0.0" iyy="0.00001" iyz="0.0" izz="0.00001" />
        <mass value="${mass}" />
        <origin xyz="0 0 0" rpy = "0 0 0"/>
      </inertial>
    </link>

    <joint name="${namespace}/gimbal_yaw_joint" type="revolute">
      <pose xyz="0 0 0" rpy = "0 0 0"/>
      <parent link="${namespace}/gimbal/base_link" />
      <child link="${namespace}/gimbal/yaw_link" />
      <limit upper="${z_rotation_range}" lower="${-1.0*z_rotation_range}" effort="1000" velocity="5000"/>
    </joint>

    <link name="${namespace}/gimbal/pitch_link">
      <inertial>
        <inertia ixx="0.00001" ixy="0.0" ixz="0.0" iyy="0.00001" iyz="0.0" izz="0.00001" />
        <mass value="${mass}" />
        <origin xyz="0 0 0" rpy = "0 0 0"/>
      </inertial>
    </link>

    <joint name="${namespace}/gimbal_pitch_joint" type="revolute">
      <origin xyz="0 0 0" rpy = "0 0 0"/>
      <parent link="${namespace}/gimbal/yaw_link" />
      <child link="${namespace}/gimbal/pitch_link" />
      <limit upper="${x_rotation_range}" lower="${-1.0*x_rotation_range}" effort="1000" velocity="5000"/>
    </joint>


    <link name="${namespace}/gimbal/roll_link">
      <inertial>
        <inertia ixx="0.00001" ixy="0.0" ixz="0.0" iyy="0.00001" iyz="0.0" izz="0.00001" />
        <mass value="${mass}" />
        <origin xyz="0 0 0" rpy = "0 0 0"/>
      </inertial>
    </link>

    <joint name="${namespace}/gimbal_roll_joint" type="revolute">
      <origin xyz="0 0 0" rpy = "0 0 0"/>
      <parent link="${namespace}/gimbal/pitch_link" />
      <child link="${namespace}/gimbal/roll_link" />
      <limit upper="${x_rotation_range}" lower="${-1.0*x_rotation_range}" effort="1000" velocity="5000"/>
    </joint>

    <!-- Attach a Laser Scanner -->
    <gazebo reference="${namespace}/gimbal/base_link">
    <sensor type="ray" name="laser_scanner">
      <pose>0 0 0 0 0 0</pose>
      <visualize>false</visualize>
      <update_rate>1</update_rate>
      <ray>
        <scan>
          <horizontal>
            <samples>720</samples>
            <resolution>1</resolution>
            <min_angle>-3.14159</min_angle>
            <max_angle>3.14159</max_angle>
          </horizontal>
        </scan>
        <range>
          <min>0.10</min>
          <max>30.0</max>
          <resolution>0.01</resolution>
        </range>
        <noise>
          <type>gaussian</type>
          <mean>0.0</mean>
          <stddev>0.01</stddev>
        </noise>
      </ray>
      <plugin name="${namespace}_laser" filename="libgazebo_ros_laser.so">
        <topicName>${namespace}/scan</topicName>
        <frameName>${namespace}/
        </frameName>
      </plugin>
    </sensor>
  </gazebo>

    <!-- Load Gimbal Controller Plugin -->
    <gazebo>
      <plugin filename="libgimbal_plugin.so" name="fcu_sim_gimbal_plugin">
        <namespace>${namespace}</namespace>
        <yawJoint>${namespace}/gimbal_yaw_joint</yawJoint>
        <pitchJoint>${namespace}/gimbal_pitch_joint</pitchJoint>
        <rollJoint>${namespace}/gimbal_roll_joint</rollJoint>
        <timeConstant>${time_constant}</timeConstant>
        <commandTopic>empty</commandTopic>
        <poseTopic>${pose_topic}</poseTopic>
        <useSlipring>true</useSlipring>
        <linkName>${parent_link}</linkName>
        <autoStabilize>true</autoStabilize>
      </plugin>
    </gazebo>
  </xacro:macro>
</robot>
